2023-05-11 09:27:24.107 | INFO     | ths_trader:__init__:51 - 进入同花顺__网上股票交易系统5.0
2023-05-11 09:27:24.109 | INFO     | ths_trader:__init__:54 - 交易应用已存在,准备开始交易
2023-05-11 09:27:25.018 | INFO     | util.date_util:in_trading_time:19 - 当前时间不在合法的交易时间内，请稍后再试
2023-05-11 09:31:32.187 | INFO     | __main__:sell_kzz:122 - ************************************************************************************
2023-05-11 09:31:32.187 | INFO     | __main__:sell_kzz:123 - 开始卖出交易，当前kzz实时行情信息:
Pandas(Index=23, 债券代码='123173', 债券名称='恒锋转债', 涨跌幅=0.86, 最新价=147.357, 最高=147.7, 最低=146.15, 今开=146.25, 涨跌额=1.257, 换手率=3.08, 量比=7.35, 动态市盈率='-', 成交量=7466, 成交额=10976642.07, 昨日收盘=146.1, 总市值=357245974, 流通市值=357245974, 行情ID='0.123173', 市场类型='深A', 更新时间='2023-05-11 09:31:27', 最新交易日='2023-05-11')
2023-05-11 09:31:35.539 | INFO     | __main__:sell_kzz:125 - 交易完成！
2023-05-11 09:31:35.540 | INFO     | __main__:sell_kzz:129 - ==========通知：在[2023-05-11 09:31:35.540992]时委托下单，以市价[147.357][0.86]涨幅卖出[恒锋转债][123173]股票[80]手
2023-05-11 09:31:35.647 | INFO     | message:send_dingding_msg:46 - 发送钉钉消息失败,错误：Traceback (most recent call last):
  File "C:\Users\ly\AppData\Local\Programs\Python\Python38\lib\site-packages\urllib3\connectionpool.py", line 700, in urlopen
    self._prepare_proxy(conn)
  File "C:\Users\ly\AppData\Local\Programs\Python\Python38\lib\site-packages\urllib3\connectionpool.py", line 996, in _prepare_proxy
    conn.connect()
  File "C:\Users\ly\AppData\Local\Programs\Python\Python38\lib\site-packages\urllib3\connection.py", line 369, in connect
    self.sock = conn = self._connect_tls_proxy(hostname, conn)
  File "C:\Users\ly\AppData\Local\Programs\Python\Python38\lib\site-packages\urllib3\connection.py", line 504, in _connect_tls_proxy
    socket = ssl_wrap_socket(
  File "C:\Users\ly\AppData\Local\Programs\Python\Python38\lib\site-packages\urllib3\util\ssl_.py", line 453, in ssl_wrap_socket
    ssl_sock = _ssl_wrap_socket_impl(sock, context, tls_in_tls)
  File "C:\Users\ly\AppData\Local\Programs\Python\Python38\lib\site-packages\urllib3\util\ssl_.py", line 495, in _ssl_wrap_socket_impl
    return ssl_context.wrap_socket(sock)
  File "C:\Users\ly\AppData\Local\Programs\Python\Python38\lib\ssl.py", line 500, in wrap_socket
    return self.sslsocket_class._create(
  File "C:\Users\ly\AppData\Local\Programs\Python\Python38\lib\ssl.py", line 1040, in _create
    self.do_handshake()
  File "C:\Users\ly\AppData\Local\Programs\Python\Python38\lib\ssl.py", line 1309, in do_handshake
    self._sslobj.do_handshake()
ssl.SSLEOFError: EOF occurred in violation of protocol (_ssl.c:1131)

During handling of the above exception, another exception occurred:

Traceback (most recent call last):
  File "C:\Users\ly\AppData\Local\Programs\Python\Python38\lib\site-packages\requests\adapters.py", line 486, in send
    resp = conn.urlopen(
  File "C:\Users\ly\AppData\Local\Programs\Python\Python38\lib\site-packages\urllib3\connectionpool.py", line 787, in urlopen
    retries = retries.increment(
  File "C:\Users\ly\AppData\Local\Programs\Python\Python38\lib\site-packages\urllib3\util\retry.py", line 592, in increment
    raise MaxRetryError(_pool, url, error or ResponseError(cause))
urllib3.exceptions.MaxRetryError: HTTPSConnectionPool(host='oapi.dingtalk.com', port=443): Max retries exceeded with url: /robot/send?access_token=1b692186495fed1ed460592f3412c5601bf1bc056d74cc9494b66c99fe04ef99&timestamp=1683768695541&sign=owbFDUTe4S3d4eikWJbaKwu4u51o6cIWhNVytuBM4w4%3D (Caused by SSLError(SSLEOFError(8, 'EOF occurred in violation of protocol (_ssl.c:1131)')))

During handling of the above exception, another exception occurred:

Traceback (most recent call last):
  File "D:\code\azuma\trade\message.py", line 40, in send_dingding_msg
    resp = requests.post(api_url,
  File "C:\Users\ly\AppData\Local\Programs\Python\Python38\lib\site-packages\requests\api.py", line 115, in post
    return request("post", url, data=data, json=json, **kwargs)
  File "C:\Users\ly\AppData\Local\Programs\Python\Python38\lib\site-packages\requests\api.py", line 59, in request
    return session.request(method=method, url=url, **kwargs)
  File "C:\Users\ly\AppData\Local\Programs\Python\Python38\lib\site-packages\requests\sessions.py", line 587, in request
    resp = self.send(prep, **send_kwargs)
  File "C:\Users\ly\AppData\Local\Programs\Python\Python38\lib\site-packages\requests\sessions.py", line 701, in send
    r = adapter.send(request, **kwargs)
  File "C:\Users\ly\AppData\Local\Programs\Python\Python38\lib\site-packages\requests\adapters.py", line 517, in send
    raise SSLError(e, request=request)
requests.exceptions.SSLError: HTTPSConnectionPool(host='oapi.dingtalk.com', port=443): Max retries exceeded with url: /robot/send?access_token=1b692186495fed1ed460592f3412c5601bf1bc056d74cc9494b66c99fe04ef99&timestamp=1683768695541&sign=owbFDUTe4S3d4eikWJbaKwu4u51o6cIWhNVytuBM4w4%3D (Caused by SSLError(SSLEOFError(8, 'EOF occurred in violation of protocol (_ssl.c:1131)')))

2023-05-11 09:31:35.648 | INFO     | __main__:sell_kzz:131 - ************************************************************************************
2023-05-11 09:31:35.649 | INFO     | __main__:sell_kzz:122 - ************************************************************************************
2023-05-11 09:31:35.649 | INFO     | __main__:sell_kzz:123 - 开始卖出交易，当前kzz实时行情信息:
Pandas(Index=28, 债券代码='128111', 债券名称='中矿转债', 涨跌幅=0.8, 最新价=552.907, 最高=556.659, 最低=546.0, 今开=547.331, 涨跌额=4.407, 换手率=5.97, 量比=5.78, 动态市盈率='-', 成交量=6564, 成交额=36267672.217, 昨日收盘=548.5, 总市值=608168949, 流通市值=608169502, 行情ID='0.128111', 市场类型='深A', 更新时间='2023-05-11 09:31:27', 最新交易日='2023-05-11')
2023-05-11 09:31:38.692 | INFO     | __main__:sell_kzz:125 - 交易完成！
2023-05-11 09:31:38.693 | INFO     | __main__:sell_kzz:129 - ==========通知：在[2023-05-11 09:31:38.692473]时委托下单，以市价[552.907][0.8]涨幅卖出[中矿转债][128111]股票[80]手
2023-05-11 09:31:38.707 | INFO     | message:send_dingding_msg:46 - 发送钉钉消息失败,错误：Traceback (most recent call last):
  File "C:\Users\ly\AppData\Local\Programs\Python\Python38\lib\site-packages\urllib3\connectionpool.py", line 700, in urlopen
    self._prepare_proxy(conn)
  File "C:\Users\ly\AppData\Local\Programs\Python\Python38\lib\site-packages\urllib3\connectionpool.py", line 996, in _prepare_proxy
    conn.connect()
  File "C:\Users\ly\AppData\Local\Programs\Python\Python38\lib\site-packages\urllib3\connection.py", line 369, in connect
    self.sock = conn = self._connect_tls_proxy(hostname, conn)
  File "C:\Users\ly\AppData\Local\Programs\Python\Python38\lib\site-packages\urllib3\connection.py", line 504, in _connect_tls_proxy
    socket = ssl_wrap_socket(
  File "C:\Users\ly\AppData\Local\Programs\Python\Python38\lib\site-packages\urllib3\util\ssl_.py", line 453, in ssl_wrap_socket
    ssl_sock = _ssl_wrap_socket_impl(sock, context, tls_in_tls)
  File "C:\Users\ly\AppData\Local\Programs\Python\Python38\lib\site-packages\urllib3\util\ssl_.py", line 495, in _ssl_wrap_socket_impl
    return ssl_context.wrap_socket(sock)
  File "C:\Users\ly\AppData\Local\Programs\Python\Python38\lib\ssl.py", line 500, in wrap_socket
    return self.sslsocket_class._create(
  File "C:\Users\ly\AppData\Local\Programs\Python\Python38\lib\ssl.py", line 1040, in _create
    self.do_handshake()
  File "C:\Users\ly\AppData\Local\Programs\Python\Python38\lib\ssl.py", line 1309, in do_handshake
    self._sslobj.do_handshake()
ssl.SSLEOFError: EOF occurred in violation of protocol (_ssl.c:1131)

During handling of the above exception, another exception occurred:

Traceback (most recent call last):
  File "C:\Users\ly\AppData\Local\Programs\Python\Python38\lib\site-packages\requests\adapters.py", line 486, in send
    resp = conn.urlopen(
  File "C:\Users\ly\AppData\Local\Programs\Python\Python38\lib\site-packages\urllib3\connectionpool.py", line 787, in urlopen
    retries = retries.increment(
  File "C:\Users\ly\AppData\Local\Programs\Python\Python38\lib\site-packages\urllib3\util\retry.py", line 592, in increment
    raise MaxRetryError(_pool, url, error or ResponseError(cause))
urllib3.exceptions.MaxRetryError: HTTPSConnectionPool(host='oapi.dingtalk.com', port=443): Max retries exceeded with url: /robot/send?access_token=1b692186495fed1ed460592f3412c5601bf1bc056d74cc9494b66c99fe04ef99&timestamp=1683768698693&sign=Yg5HRnvE%2FZeCq0VNJcbB6lxjO5BV%2BJKSNLiu6xjHG5c%3D (Caused by SSLError(SSLEOFError(8, 'EOF occurred in violation of protocol (_ssl.c:1131)')))

During handling of the above exception, another exception occurred:

Traceback (most recent call last):
  File "D:\code\azuma\trade\message.py", line 40, in send_dingding_msg
    resp = requests.post(api_url,
  File "C:\Users\ly\AppData\Local\Programs\Python\Python38\lib\site-packages\requests\api.py", line 115, in post
    return request("post", url, data=data, json=json, **kwargs)
  File "C:\Users\ly\AppData\Local\Programs\Python\Python38\lib\site-packages\requests\api.py", line 59, in request
    return session.request(method=method, url=url, **kwargs)
  File "C:\Users\ly\AppData\Local\Programs\Python\Python38\lib\site-packages\requests\sessions.py", line 587, in request
    resp = self.send(prep, **send_kwargs)
  File "C:\Users\ly\AppData\Local\Programs\Python\Python38\lib\site-packages\requests\sessions.py", line 701, in send
    r = adapter.send(request, **kwargs)
  File "C:\Users\ly\AppData\Local\Programs\Python\Python38\lib\site-packages\requests\adapters.py", line 517, in send
    raise SSLError(e, request=request)
requests.exceptions.SSLError: HTTPSConnectionPool(host='oapi.dingtalk.com', port=443): Max retries exceeded with url: /robot/send?access_token=1b692186495fed1ed460592f3412c5601bf1bc056d74cc9494b66c99fe04ef99&timestamp=1683768698693&sign=Yg5HRnvE%2FZeCq0VNJcbB6lxjO5BV%2BJKSNLiu6xjHG5c%3D (Caused by SSLError(SSLEOFError(8, 'EOF occurred in violation of protocol (_ssl.c:1131)')))

2023-05-11 09:31:38.708 | INFO     | __main__:sell_kzz:131 - ************************************************************************************
